import { NextFunction, Request, Response } from "express";
import { HttpException, ErrorCode } from "../exceptions/root";
import { InternalException } from "../exceptions/internal-exception"

//Manejador de errores
export const errorHandler = (method: Function) => {
    return async(req: Request, res: Response, next: NextFunction) => {
        try {
           await method(req, res, next)
        } catch(error: any) {
            let exception: HttpException;
            if( error instanceof HttpException){
                exception = error;
            }else{
                exception = new InternalException('Something went wrong!', error, ErrorCode.INTERNAL_EXCEPTION);
            }
            next(exception)
        }

    }
}
